<?xml version='1.0' encoding='utf-8'?>
<robot name="amr">

    <link name="base_footprint"/>

    <link name="base_link">
        <inertial>
            <origin xyz="0.008984021257939274 -6.479702430833408e-06 0.007183147979859465" rpy="0.0 0.0 0.0" />
            <mass value="54.6833120617988" />
            <inertia ixx="1.5659847831549638" iyy="3.443385977550992" izz="4.748189007356874" ixy="0.00013830393033976336" iyz="-5.1166592165003865e-05" ixz="0.06295371986717117" />
        </inertial>
        <visual name="base_link_visual">
            <origin xyz="0.0 0.0 0.0" rpy="0.0 0.0 0.0" />
            <geometry>
                <mesh filename="package://tr_sim/robots/meshes/base_link.stl" scale="0.001 0.001 0.001" />
            </geometry>
        </visual>
        <collision name="base_link_collision">
            <origin xyz="0.0 0.0 0.0" rpy="0.0 0.0 0.0" />
            <geometry>
                <mesh filename="package://tr_sim/robots/meshes/base_link.stl" scale="0.001 0.001 0.001" />
            </geometry>
        </collision>
    </link>

    <joint name="base_link_joint" type="fixed">
        <origin xyz="0 0 0" rpy="0 0 0"/>
        <parent link="base_footprint"/>
        <child  link="base_link"/>
    </joint>

    <link name="caster_bogie_rear">
        <inertial>
            <origin xyz="0.022843532023450682 -2.6330366663922857e-05 -0.0007734416612576212" rpy="0.0 -0.0 0.0" />
            <mass value="9.448653015709194" />
            <inertia ixx="0.22192357862634726" iyy="0.023840312612585013" izz="0.20101256143449134" ixy="-2.826767879802418e-06" iyz="2.3576305284251037e-07" ixz="-2.4503293384270375e-05" />
        </inertial>
        <visual name="caster_bogie_rear_visual">
            <origin xyz="0.0 0.0 0.0" rpy="-0.0 1.5708 0" />
            <geometry>
                <mesh filename="package://tr_sim/robots/meshes/caster_bogie_rear.stl" scale="0.001 0.001 0.001" />
            </geometry>
        </visual>
        <collision name="caster_bogie_rear_collision">
            <origin xyz="0.0 0.0 0.0" rpy="-0.0 1.5708 0" />
            <geometry>
                <mesh filename="package://tr_sim/robots/meshes/caster_bogie_rear.stl" scale="0.001 0.001 0.001" />
            </geometry>
        </collision>
    </link>

    <joint name="caster_bogie_rear_joint" type="revolute">
        <origin xyz="-0.3 0.0 -0.053" rpy="-0.0 -1.5708 0" />
        <parent link="base_link" />
        <child link="caster_bogie_rear" />
        <axis xyz="0.0 0.0 1.0" />
        <limit lower="-0.024435" upper="0.024435" effort="1000000" velocity="1000000" />
    </joint>

    <link name="lidar_front" type="laser">
        <inertial>
            <origin xyz="-0.0021555131561702013 -4.6249725756491665e-05 -0.07329643431777715" rpy="0.0 -0.0 0.0" />
            <mass value="4.719510299398373" />
            <inertia ixx="0.005806550370805789" iyy="0.005598361277714625" izz="0.006586524732465127" ixy="1.0334164918979528e-05" iyz="2.945849772183217e-06" ixz="-1.4112960063789037e-07" />
        </inertial>
        <visual name="lidar_front_visual">
            <origin xyz="0.0 0.0 0.04" rpy="3.1416 -0.0 0.0" />
            <geometry>
                <mesh filename="package://tr_sim/robots/meshes/lidar_front.stl" scale="0.001 0.001 0.001" />
            </geometry>
        </visual>
        <collision name="lidar_front_collision">
            <origin xyz="0.0 0.0 0.04" rpy="3.1416 -0.0 0.0" />
            <geometry>
                <mesh filename="package://tr_sim/robots/meshes/lidar_front.stl" scale="0.001 0.001 0.001" />
            </geometry>
        </collision>
    </link>

    <joint name="lidar_front_joint" type="fixed">
        <origin xyz="0.352 0.226 0.04" rpy="3.1416 0.0 0.7854" />
        <parent link="base_link" />
        <child link="lidar_front" />
    </joint>

    <link name="lidar_rear" type="laser">
        <inertial>
            <origin xyz="0.0021555131561695616 4.6249724567336404e-05 -0.073296434317777075" rpy="0.0 -0.0 0.0" />
            <mass value="4.719510299398373" />
            <inertia ixx="0.005806550370805826" iyy="0.005598361277714625" izz="0.006586524732465127" ixy="1.0334164918981344e-05" iyz="-2.945849772183206e-06" ixz="1.4112960064482927e-07" />
        </inertial>
        <visual name="lidar_rear_visual">
            <origin xyz="0.0 0.0 0.04" rpy="3.1416 -0.0 -3.1416" />
            <geometry>
                <mesh filename="package://tr_sim/robots/meshes/lidar_rear.stl" scale="0.001 0.001 0.001" />
            </geometry>
        </visual>
        <collision name="lidar_rear_collision">
            <origin xyz="0.0 0.0 0.04" rpy="3.1416 -0.0 -3.1416" />
            <geometry>
                <mesh filename="package://tr_sim/robots/meshes/lidar_rear.stl" scale="0.001 0.001 0.001" />
            </geometry>
        </collision>
    </link>

    <joint name="lidar_rear_joint" type="fixed">
        <origin xyz="-0.352 -0.226 0.04" rpy="3.1416 -0.0 0.7854" />
        <parent link="base_link" />
        <child link="lidar_rear" />
    </joint>

    <link name="wheel_bogie_right">
        <inertial>
            <origin xyz="-0.06852111959933944 -0.018732454336378847 -0.025925392445573757" rpy="0.0 -5.344641074283642e-135 0.0" />
            <mass value="17.24320821275693" />
            <inertia ixx="0.06908778796213966" iyy="0.3060923823530777" izz="0.2934415419307673" ixy="-0.04875551501001229" iyz="-0.015331320179237847" ixz="-0.038696850953745573" />
        </inertial>
        <visual name="wheel_bogie_right_visual">
            <origin xyz="0.0 0.0 0.0" rpy="-1.5708 0.0 0.0" />
            <geometry>
                <mesh filename="package://tr_sim/robots/meshes/wheel_bogie_right.stl" scale="0.001 0.001 0.001" />
            </geometry>
        </visual>
        <collision name="wheel_bogie_right_collision">
            <origin xyz="0.0 0.0 0.0" rpy="-1.5708 0.0 0.0" />
            <geometry>
                <mesh filename="package://tr_sim/robots/meshes/wheel_bogie_right.stl" scale="0.001 0.001 0.001" />
            </geometry>
        </collision>
    </link>

    <joint name="wheel_bogie_right_joint" type="revolute">
        <origin xyz="0.155 -0.2 -0.063" rpy="1.5707963267948966 -4.025490512338682e-75 -3.03192929884458e-15" />
        <parent link="base_link" />
        <child link="wheel_bogie_right" />
        <axis xyz="0.0 0.0 1.0" />
        <limit lower="-0.10472" upper="0.10472" effort="1000000" velocity="1000000" />
    </joint>

    <link name="wheel_bogie_left">
        <inertial>
            <origin xyz="-0.06850975651670765 0.018732454336393804 -0.02593673502556399" rpy="0.0 -0.0 0.0" />
            <mass value="17.243208212756965" />
            <inertia ixx="0.06907764463880628" iyy="0.3060483481515104" izz="0.2934076510525332" ixy="0.048762810188188975" iyz="0.015326512061298963" ixz="-0.03864365286747225" />
        </inertial>
        <visual name="wheel_bogie_left_visual">
            <origin xyz="0.0 0.0 0.0" rpy="1.5708 0.0 0.0" />
            <geometry>
                <mesh filename="package://tr_sim/robots/meshes/wheel_bogie_left.stl" scale="0.001 0.001 0.001" />
            </geometry>
        </visual>
        <collision name="wheel_bogie_left_collision">
            <origin xyz="0.0 0.0 0.0" rpy="1.5708 0.0 0.0" />
            <geometry>
                <mesh filename="package://tr_sim/robots/meshes/wheel_bogie_left.stl" scale="0.001 0.001 0.001" />
            </geometry>
        </collision>
    </link>

    <joint name="wheel_bogie_left_joint" type="revolute">
        <origin xyz="0.155 0.2 -0.063" rpy="-1.5707963267948974 -0.0 0.0" />
        <parent link="base_link" />
        <child link="wheel_bogie_left" />
        <axis xyz="0.0 0.0 1.0" />
        <limit lower="-0.10472" upper="0.10472" effort="1000000" velocity="1000000" />
    </joint>

    <link name="wheel_left">
        <inertial>
            <origin xyz="2.6673008745215307e-06 3.3143265909529875e-13 -0.032058475531007" rpy="0.0 -0.0 0.0" />
            <mass value="8.00705817464069" />
            <inertia ixx="0.012472469794906682" iyy="0.01247230181684228" izz="0.01865454238066705" ixy="-9.623100204658339e-22" iyz="1.3727331635459947e-18" ixz="-5.191617839414687e-07" />
        </inertial>
        <visual name="wheel_left_visual">
            <origin xyz="0.0 0.0 -0.03" rpy="-1.5708 0.0 0.0" />
            <geometry>
                <mesh filename="package://tr_sim/robots/meshes/wheel_left.stl" scale="0.001 0.001 0.001" />
            </geometry>
        </visual>
        <collision name="wheel_left_collision">
            <origin xyz="0.0 0.0 -0.03" rpy="0.0 0.0 0.0" />
            <geometry>
                <!-- <mesh filename="package://tr_sim/robots/meshes/wheel_left.stl" scale="0.001 0.001 0.001" /> -->
                <cylinder radius="0.075" length="0.04"/>
            </geometry>
        </collision>
    </link>

    <joint name="wheel_left_joint" type="continuous">
        <origin xyz="-0.155 0.055 0.01" rpy="-3.1416 0.0 0.0" />
        <parent link="wheel_bogie_left" />
        <child link="wheel_left" />
        <axis xyz="0.0 0.0 -1.0" />
    </joint>

    <link name="wheel_right">
        <inertial>
            <origin xyz="-2.6673008833655347e-06 -3.466382736405649e-13 -0.03205847553053328" rpy="0.0 -0.0 0.0" />
            <mass value="8.007058174640683" />
            <inertia ixx="0.012472469794907126" iyy="0.012472301816842335" izz="0.018654542380666994" ixy="-5.711427886262538e-18" iyz="2.9128308779174844e-17" ixz="5.191617839298982e-07" />
        </inertial>
        <visual name="wheel_right_visual">
            <origin xyz="0.0 0.0 -0.03" rpy="1.5708 0.0 0.0" />
            <geometry>
                <mesh filename="package://tr_sim/robots/meshes/wheel_right.stl" scale="0.001 0.001 0.001" />
            </geometry>
        </visual>
        <collision name="wheel_right_collision">
            <origin xyz="0.0 0.0 -0.03" rpy="0.0 0.0 0.0" />
            <geometry>
                <!-- <mesh filename="package://tr_sim/robots/meshes/wheel_right.stl" scale="0.001 0.001 0.001" /> -->
                <cylinder radius="0.075" length="0.04"/>
            </geometry>
        </collision>
    </link>

    <joint name="wheel_right_joint" type="continuous">
        <origin xyz="-0.155 -0.055 0.01" rpy="-3.1416 0.0 0.0" />
        <parent link="wheel_bogie_right" />
        <child link="wheel_right" />
        <axis xyz="0.0 0.0 -1.0" />
    </joint>

    <link name="caster_fork_front_left">
        <inertial>
            <origin xyz="-0.00672487834254163 -1.584393061193623e-11 0.029095940008567755" rpy="0.0 -0.0 0.0" />
            <mass value="1.9429304122688102" />
            <inertia ixx="0.0035664553510987435" iyy="0.0027738795072598244" izz="0.003140501764999526" ixy="9.957412450134484e-09" iyz="5.9724137232985974e-09" ixz="0.0005902573302670674" />
        </inertial>
        <visual name="caster_fork_front_left_visual">
            <origin xyz="0.0 0.0 0.0" rpy="3.1416 0.0 0.0" />
            <geometry>
                <mesh filename="package://tr_sim/robots/meshes/caster_fork_front_left.stl" scale="0.001 0.001 0.001" />
            </geometry>
        </visual>
        <collision name="caster_fork_front_left_collision">
            <origin xyz="0.0 0.0 0.0" rpy="3.1416 -0.0 0.0" />
            <geometry>
                <mesh filename="package://tr_sim/robots/meshes/caster_fork_front_left.stl" scale="0.001 0.001 0.001" />
            </geometry>
        </collision>
    </link>

    <joint name="caster_fork_front_left_joint" type="continuous">
        <origin xyz="0.155 0.0 0.0" rpy="-1.5708 0.0 0.0" />
        <parent link="wheel_bogie_left" />
        <child link="caster_fork_front_left" />
        <axis xyz="-0.0 0.0 1.0" />
    </joint>

    <link name="caster_fork_front_right">
        <inertial>
            <origin xyz="-0.0067248783425351635 -1.4218883848116094e-11 0.029095940008552867" rpy="0.0 -0.0 0.0" />
            <mass value="1.9429304122688102" />
            <inertia ixx="0.0035664553510987573" iyy="0.0027738795072598244" izz="0.0031405017649995814" ixy="9.957412491767847e-09" iyz="5.9724137232985974e-09" ixz="0.0005902573302670605" />
        </inertial>
        <visual name="caster_fork_front_right_visual">
            <origin xyz="0.0 0.0 0.0" rpy="3.1416 0.0 0.0" />
            <geometry>
                <mesh filename="package://tr_sim/robots/meshes/caster_fork_front_right.stl" scale="0.001 0.001 0.001" />
            </geometry>
        </visual>
        <collision name="caster_fork_front_right_collision">
            <origin xyz="0.0 0.0 0.0" rpy="3.1416 -0.0 0.0" />
            <geometry>
                <mesh filename="package://tr_sim/robots/meshes/caster_fork_front_right.stl" scale="0.001 0.001 0.001" />
            </geometry>
        </collision>
    </link>

    <joint name="caster_fork_front_right_joint" type="continuous">
        <origin xyz="0.155 0.0 0.0" rpy="1.5708 0.0 0.0" />
        <parent link="wheel_bogie_right" />
        <child link="caster_fork_front_right" />
        <axis xyz="0.0 -0.0 1.0" />
    </joint>

    <link name="caster_wheel_front_left">
        <inertial>
            <origin xyz="-2.468425464030588e-13 7.176481631177012e-15 -0.0014999999989512604" rpy="0.0 4.5339884914245834e-77 0.0" />
            <mass value="3.2417236506323017" />
            <inertia ixx="0.0031031422960176858" iyy="0.0031031422960486887" izz="0.0040294318982639354" ixy="3.749778265671466e-14" iyz="4.591514576119539e-30" ixz="-2.786901337527635e-17" />
        </inertial>
        <visual name="caster_wheel_front_left_visual">
            <origin xyz="0.0 0.0 -0.0015" rpy="1.5708 0.0 0.0" />
            <geometry>
                <mesh filename="package://tr_sim/robots/meshes/caster_wheel_front_left.stl" scale="0.001 0.001 0.001" />
            </geometry>
        </visual>
        <collision name="caster_wheel_front_left_collision">
            <origin xyz="0.0 0.0 -0.0015" rpy="0.0 0.0 0.0" />
            <geometry>
                <!-- <mesh filename="package://tr_sim/robots/meshes/caster_wheel_front_left.stl" scale="0.001 0.001 0.001" /> -->
                <!-- <cylinder radius="0.0495" length="0.063"/> -->
                <sphere radius="0.0495"/>
            </geometry>
        </collision>
    </link>

    <joint name="caster_wheel_front_left_joint" type="continuous">
        <origin xyz="-0.03 0.0 0.08" rpy="1.5708 0.0 0.0" />
        <parent link="caster_fork_front_left" />
        <child link="caster_wheel_front_left" />
        <axis xyz="0.0 0.0 1.0" />
    </joint>

    <link name="caster_wheel_front_right">
        <inertial>
            <origin xyz="-2.403766075076419e-13 -7.762679388179095e-15 -0.0015000000005761295" rpy="0.0 1.0188616376499416e-76 0.0" />
            <mass value="3.2417236506323017" />
            <inertia ixx="0.0031031422960176858" iyy="0.0031031422960487443" izz="0.004029431898263991" ixy="3.7470027081099033e-14" iyz="1.3877787807819045e-17" ixz="2.7642137855981472e-17" />
        </inertial>
        <visual name="caster_wheel_front_right_visual">
            <origin xyz="0.0 0.0 -0.0015" rpy="1.5708 0.0 0.0" />
            <geometry>
                <mesh filename="package://tr_sim/robots/meshes/caster_wheel_front_right.stl" scale="0.001 0.001 0.001" />
            </geometry>
        </visual>
        <collision name="caster_wheel_front_right_collision">
            <origin xyz="0.0 0.0 -0.0015" rpy="0.0 0.0 0.0" />
            <geometry>
                <!-- <mesh filename="package://tr_sim/robots/meshes/caster_wheel_front_right.stl" scale="0.001 0.001 0.001" /> -->
                <!-- <cylinder radius="0.0495" length="0.063"/> -->
                <sphere radius="0.0495"/>
            </geometry>
        </collision>
    </link>

    <joint name="caster_wheel_front_right_joint" type="continuous">
        <origin xyz="-0.03 0.0 0.08" rpy="1.5707963267948966 1.1170253548250512e-46 1.2246467991473535e-16" />
        <parent link="caster_fork_front_right" />
        <child link="caster_wheel_front_right" />
        <axis xyz="0.0 0.0 1.0" />
    </joint>

    <link name="caster_fork_rear_left">
        <inertial>
            <origin xyz="-0.007131927702338388 6.729550250383909e-13 0.02721677455228134" rpy="0.0 -0.0 0.0" />
            <mass value="2.4128549551628136" />
            <inertia ixx="0.00562341303193864" iyy="0.004408879848199765" izz="0.0054715960333791" ixy="1.226491004591157e-08" iyz="5.475928873538427e-09" ixz="0.0008659928765132746" />
        </inertial>
        <visual name="caster_fork_rear_left_visual">
            <origin xyz="0.0 0.0 0.0" rpy="3.1416 -0.0 0.0" />
            <geometry>
                <mesh filename="package://tr_sim/robots/meshes/caster_fork_rear_left.stl" scale="0.001 0.001 0.001" />
            </geometry>
        </visual>
        <collision name="caster_fork_rear_left_collision">
            <origin xyz="0.0 0.0 0.0" rpy="3.1416 -0.0 0.0" />
            <geometry>
                <mesh filename="package://tr_sim/robots/meshes/caster_fork_rear_left.stl" scale="0.001 0.001 0.001" />
            </geometry>
        </collision>
    </link>

    <joint name="caster_fork_rear_left_joint" type="continuous">
        <origin xyz="0.011 0.155 -0.00028" rpy="-3.141592653589793 1.5707963267948966 0" />
        <parent link="caster_bogie_rear" />
        <child link="caster_fork_rear_left" />
        <axis xyz="0.0 0.0 1.0" />
    </joint>

    <link name="caster_fork_rear_right">
        <inertial>
            <origin xyz="-0.007131927702338388 6.719425016399327e-13 0.027216774553862334" rpy="0.0 -0.0 0.0" />
            <mass value="2.4128549551628136" />
            <inertia ixx="0.005623413031938626" iyy="0.004408879848199709" izz="0.0054715960333791" ixy="1.2264910059789358e-08" iyz="5.475928866599533e-09" ixz="0.0008659928765132677" />
        </inertial>
        <visual name="caster_fork_rear_right_visual">
            <origin xyz="0.0 0.0 0.0" rpy="3.1416 -0.0 0.0" />
            <geometry>
                <mesh filename="package://tr_sim/robots/meshes/caster_fork_rear_right.stl" scale="0.001 0.001 0.001" />
            </geometry>
        </visual>
        <collision name="caster_fork_rear_right_collision">
            <origin xyz="0.0 0.0 0.0" rpy="3.1416 -0.0 0.0" />
            <geometry>
                <mesh filename="package://tr_sim/robots/meshes/caster_fork_rear_right.stl" scale="0.001 0.001 0.001" />
            </geometry>
        </collision>
    </link>

    <joint name="caster_fork_rear_right_joint" type="continuous">
        <origin xyz="0.011 -0.155 -0.00028" rpy="-3.1416 1.5708 0" />
        <parent link="caster_bogie_rear" />
        <child link="caster_fork_rear_right" />
        <axis xyz="0.0 0.0 1.0" />
    </joint>

    <link name="caster_wheel_rear_left">
        <inertial>
            <origin xyz="-6.782785533232527e-10 -6.020073328727449e-13 0.0019999999985684446" rpy="0.0 7.322611459065929e-49 0.0" />
            <mass value="5.360084509072765" />
            <inertia ixx="0.007934793862015427" iyy="0.007934793862015788" izz="0.010879339821361467" ixy="-3.0321325412231968e-40" iyz="7.183618055560104e-14" ixz="-1.2428630744851414e-29" />
        </inertial>
        <visual name="caster_wheel_rear_left_visual">
            <origin xyz="0.0 0.0 0.002" rpy="1.5708 0.0 0.0" />
            <geometry>
                <mesh filename="package://tr_sim/robots/meshes/caster_wheel_rear_left.stl" scale="0.001 0.001 0.001" />
            </geometry>
        </visual>
        <collision name="caster_wheel_rear_left_collision">
            <origin xyz="0.0 0.0 0.002" rpy="0.0 0.0 0.0" />
            <geometry>
                <!-- <mesh filename="package://tr_sim/robots/meshes/caster_wheel_rear_left.stl" scale="0.001 0.001 0.001" /> -->
                <!-- <cylinder radius="0.0615" length="0.074"/> -->
                <sphere radius="0.0615"/>
            </geometry>
        </collision>
    </link>

    <joint name="caster_wheel_rear_left_joint" type="continuous">
        <origin xyz="-0.033 0.0 0.0885" rpy="1.5708 0.0 0.0" />
        <parent link="caster_fork_rear_left" />
        <child link="caster_wheel_rear_left" />
        <axis xyz="0.0 0.0 1.0" />
    </joint>

    <link name="caster_wheel_rear_right">
        <inertial>
            <origin xyz="-6.782785533232527e-10 9.78950254193478e-13 0.001999999998569475" rpy="0.0 7.322611459065929e-49 0.0" />
            <mass value="5.360084509072765" />
            <inertia ixx="0.007934793862015399" iyy="0.007934793862015677" izz="0.010879339821361467" ixy="-2.7755575615628914e-17" iyz="7.183618055559958e-14" ixz="-3.7800722617366307e-28" />
        </inertial>
        <visual name="caster_wheel_rear_right_visual">
            <origin xyz="0.0 0.0 0.002" rpy="1.5708 0.0 0.0" />
            <geometry>
                <mesh filename="package://tr_sim/robots/meshes/caster_wheel_rear_right.stl" scale="0.001 0.001 0.001" />
            </geometry>
        </visual>
        <collision name="caster_wheel_rear_right_collision">
            <origin xyz="0.0 0.0 0.002" rpy="0.0 0.0 0.0" />
            <geometry>
                <!-- <mesh filename="package://tr_sim/robots/meshes/caster_wheel_rear_right.stl" scale="0.001 0.001 0.001" /> -->
                <!-- <cylinder radius="0.0615" length="0.074"/> -->
                <sphere radius="0.0615"/>
            </geometry>
        </collision>
    </link>

    <joint name="caster_wheel_rear_right_joint" type="continuous">
        <origin xyz="-0.033 0.0 0.0885" rpy="1.5708 0.0 0.0" />
        <parent link="caster_fork_rear_right" />
        <child link="caster_wheel_rear_right" />
        <axis xyz="0.0 0.0 1.0" />
    </joint>

</robot>